Workbook

Sheet Cleaned Data
A1: name | B1: planet_status | C1: mass | D1: mass_error_min | E1: mass_error_max | F1: mass_sini | G1: mass_sini_error_min | H1: mass_sini_error_max | I1: radius | J1: radius_error_min
A2: 109 Psc b | B2: Confirmed | C2: 5.743 | D2: 0.289 | E2: 1.011 | F2: 6.383 | G2: 0.078 | H2: 0.078 | I2: 1.152
A3: 112 Psc b | B3: Confirmed | D3: 0.005 | E3: 0.004 | F3: 0.033 | G3: 0.005 | H3: 0.004
A4: 112 Psc c | B4: Confirmed | C4: 9.866 | D4: 1.781 | E4: 3.19
A5: 11 UMi b | B5: Confirmed | D5: 1.1 | E5: 1.1 | F5: 11.0873 | G5: 1.1 | H5: 1.1
A6: 14 And Ab | B6: Confirmed | D6: 0.23 | E6: 0.23 | F6: 4.684 | G6: 0.23 | H6: 0.23
A7: 14 Her b | B7: Confirmed | C7: 8.9 | D7: 1.7 | E7: 1.3 | F7: 4.95
A8: 14 Her c | B8: Confirmed | C8: 7.9 | D8: 1.2 | E8: 1.6 | F8: 7.12
A9: 16 Cyg Bb | B9: Confirmed | D9: 0.08 | E9: 0.08 | F9: 1.64 | G9: 0.08 | H9: 0.08
A10: 18 Del Ab | B10: Confirmed | D10: 0.36 | E10: 0.36 | F10: 10.3 | G10: 0.36 | H10: 0.36
A11: 23 Lib b | B11: Confirmed | D11: 0.02 | E11: 0.02 | F11: 1.59 | G11: 0.02 | H11: 0.02
A12: 23 Lib c | B12: Confirmed | D12: 0.03 | E12: 0.03 | F12: 0.82 | G12: 0.03 | H12: 0.03
A13: 24 Boo b | B13: Confirmed | D13: 0.11 | E13: 0.11 | F13: 0.91 | G13: 0.11 | H13: 0.11
A14: 24 Sex b | B14: Confirmed | D14: 0.11 | E14: 0.11 | F14: 1.84 | G14: 0.11 | H14: 0.11
A15: 24 Sex c | B15: Confirmed | D15: 0.2 | E15: 0.2 | F15: 1.52 | G15: 0.2 | H15: 0.2
A16: 2M 1253+2734 b | B16: Confirmed | D16: 0.2 | E16: 1.8 | F16: 8.3 | G16: 0.2 | H16: 1.8
A17: 2M1510 (AB)b | B17: Confirmed | C17: 0.031
A18: 2MASS J0437+2651 b | B18: Confirmed | C18: 4
A19: 2MASS J0558-4501 b | B19: Confirmed | C19: 9 | D19: 3 | E19: 3
A20: 2MASS J1155-7919 b | B20: Confirmed | C20: 10
A21: 2MASS J1252+2735 b | B21: Confirmed | D21: 0.64 | E21: 0.21 | F21: 6.88 | G21: 0.64 | H21: 0.21
A22: 2MASS J1258+2630 b | B22: Confirmed | D22: 0.18 | E22: 0.31 | F22: 3.4 | G22: 0.18 | H22: 0.31
A23: 2MASS J2236+4751 b | B23: Confirmed | C23: 12.5 | D23: 1.5 | E23: 1.5
A24: 38 Vir b | B24: Confirmed | D24: 0.5 | E24: 0.5 | F24: 4.51 | G24: 0.5 | H24: 0.5
A25: 41 Com Ab | B25: Confirmed | D25: 1 | E25: 1 | F25: 6.3 | G25: 1 | H25: 1
A26: 44 Uma b | B26: Confirmed | D26: 0.85 | E26: 0.2 | F26: 12.11 | G26: 0.85 | H26: 0.2
A27: 47 UMa b | B27: Confirmed | D27: 0.06 | E27: 0.07 | F27: 2.53 | G27: 0.06 | H27: 0.07
A28: 47 UMa c | B28: Confirmed | D28: 0.073 | E28: 0.066 | F28: 0.54 | G28: 0.073 | H28: 0.066
A29: 47 UMa d | B29: Confirmed | D29: 0.48 | E29: 0.29 | F29: 1.64 | G29: 0.48 | H29: 0.29
A30: 51 Eri Ab | B30: Confirmed | C30: 4.1 | D30: 0.5 | E30: 0.5 | I30: 1.11 | J30: 0.13
A31: 51 Peg b | B31: Confirmed | C31: 0.47 | D31: 0.07 | E31: 0.03 | F31: 0.46 | G31: 0.06 | H31: 0.01 | I31: 1.9 | J31: 0.3
A32: 54 Psc b | B32: Confirmed | C32: 0.23 | D32: 0.013 | E32: 0.297 | F32: 0.228 | G32: 0.011 | H32: 0.011
A33: 55 Cnc Ab | B33: Confirmed | C33: 0.84 | D33: 0.031 | E33: 0.23 | F33: 0.84 | G33: 0.031 | H33: 0.131
A34: 55 Cnc Ac | B34: Confirmed | D34: 0.0078 | E34: 0.0275 | F34: 0.1784 | G34: 0.0078 | H34: 0.0275
A35: 55 Cnc Ad | B35: Confirmed | D35: 0.08 | E35: 0.08 | F35: 3.84 | G35: 0.08 | H35: 0.08
A36: 55 Cnc Ae | B36: Confirmed | C36: 0.02703 | D36: 0.00135 | E36: 0.00135 | I36: 0.1737 | J36: 0.00339
A37: 55 Cnc Af | B37: Confirmed | D37: 0.0093 | E37: 0.0219 | F37: 0.1479 | G37: 0.0093 | H37: 0.0219
A38: 61 Vir b | B38: Confirmed | D38: 0.0016 | E38: 0.0016 | F38: 0.016 | G38: 0.0016 | H38: 0.0016
A39: 61 Vir c | B39: Confirmed | D39: 0.0035 | E39: 0.0035 | F39: 0.0573 | G39: 0.0035 | H39: 0.0035
A40: 61 Vir d | B40: Confirmed | D40: 0.008 | E40: 0.008 | F40: 0.072 | G40: 0.008 | H40: 0.008
...

Sheet Analysis
A1: Planet Analysis
A3: Metric | B3: Result
A4: Highest Mass | B4: =MAX('Cleaned Data'!C:C) -> 12.934
A5: Planet with Highest Mass | B5: {=INDEX('Cleaned Data'!A:A,MATCH(B4,'Cleaned Data'!C:C,0))} -> GJ 2030 Ac
A6: Lowest Mass | B6: =MIN('Cleaned Data'!C:C) -> 0.00019
A7: Planet with Lowest Mass | B7: {=INDEX('Cleaned Data'!A:A,MATCH(B6,'Cleaned Data'!C:C,0))} -> LHS 1678 b
A8: Average Mass | B8: =AVERAGE('Cleaned Data'!C:C) -> 1.4925385
A9: Average Radius | B9: =AVERAGE('Cleaned Data'!I:I) -> 0.40151504
A11: Planet Status | B11: Number of Planets
A12: Confirmed | B12: =COUNTIF('Cleaned Data'!B:B,A12) -> 5986
A15: Top 10 Planets by Mass
A17: Rank | B17: Planet Name | C17: Mass
A18: 1 | B18: {=INDEX('Cleaned Data'!A:A,MATCH(C18,'Cleaned Data'!C:C,0))} -> GJ 2030 Ac | C18: =LARGE('Cleaned Data'!C:C,A18) -> 12.934
A19: 2 | B19: {=INDEX('Cleaned Data'!A:A,MATCH(C19,'Cleaned Data'!C:C,0))} -> HATS-70 b | C19: =LARGE('Cleaned Data'!C:C,A19) -> 12.9
A20: 3 | B20: {=INDEX('Cleaned Data'!A:A,MATCH(C20,'Cleaned Data'!C:C,0))} -> TOI-4603 b | C20: =LARGE('Cleaned Data'!C:C,A20) -> 12.89
A21: 4 | B21: {=INDEX('Cleaned Data'!A:A,MATCH(C21,'Cleaned Data'!C:C,0))} -> HD 11506 d | C21: =LARGE('Cleaned Data'!C:C,A21) -> 12.8
A22: 5 | B22: {=INDEX('Cleaned Data'!A:A,MATCH(C22,'Cleaned Data'!C:C,0))} -> HD 11506 d | C22: =LARGE('Cleaned Data'!C:C,A22) -> 12.8
A23: 6 | B23: {=INDEX('Cleaned Data'!A:A,MATCH(C23,'Cleaned Data'!C:C,0))} -> TIC 4672985 | C23: =LARGE('Cleaned Data'!C:C,A23) -> 12.74
A24: 7 | B24: {=INDEX('Cleaned Data'!A:A,MATCH(C24,'Cleaned Data'!C:C,0))} -> pi Men b | C24: =LARGE('Cleaned Data'!C:C,A24) -> 12.6
A25: 8 | B25: {=INDEX('Cleaned Data'!A:A,MATCH(C25,'Cleaned Data'!C:C,0))} -> HD 149806 Ab | C25: =LARGE('Cleaned Data'!C:C,A25) -> 12.597
A26: 9 | B26: {=INDEX('Cleaned Data'!A:A,MATCH(C26,'Cleaned Data'!C:C,0))} -> 2MASS J2236+4751 b | C26: =LARGE('Cleaned Data'!C:C,A26) -> 12.5
A27: 10 | B27: {=INDEX('Cleaned Data'!A:A,MATCH(C27,'Cleaned Data'!C:C,0))} -> TOI-4987 b | C27: =LARGE('Cleaned Data'!C:C,A27) -> 12.37

Sheet Dashboard
A1: PLANET DATA VISUALIZATION DASHBOARD
A3: Planet Analysis | Data Visualization
A5: Highest Mass | C5: Lowest Mass | E5: Average Mass | G5: Average Radius
A6: =Analysis!B4 -> 12.934 | C6: =Analysis!B6 -> 0.00019 | E6: =Analysis!B8 -> 1.4925385 | G6: =Analysis!B9 -> 0.40151504
A7: Highest Mass Planet | B7: =Analysis!B5 -> GJ 2030 Ac | C7: Lowest Mass Planet | D7: =Analysis!B7 -> LHS 1678 b
